<?xml version="1.0"?>

<robot name="teslabot">

<link name="base_link">

  <visual>
    <geometry>
      <box size="0.5 0.5 0.2"/>
    </geometry>
  </visual>

  <collision>
    <geometry>
      <box size="0.5 0.5 0.2"/>
    </geometry>
  </collision>

  <inertial>
    <mass value="1"/>
    <origin xyz="0 0 0"/>
    <inertia ixx="0.1" ixy="0" ixz="0"
             iyy="0.1" iyz="0"
             izz="0.1"/>
  </inertial>

</link>


<link name="arm_link">

  <visual>
    <geometry>
      <box size="0.1 0.1 0.6"/>
    </geometry>
  </visual>

  <collision>
    <geometry>
      <box size="0.1 0.1 0.6"/>
    </geometry>
  </collision>

  <inertial>
    <mass value="0.5"/>
    <origin xyz="0 0 0"/>
    <inertia ixx="0.05" ixy="0" ixz="0"
             iyy="0.05" iyz="0"
             izz="0.05"/>
  </inertial>

</link>


<joint name="arm_joint" type="revolute">

  <parent link="base_link"/>
  <child link="arm_link"/>

  <origin xyz="0 0 0.4" rpy="0 0 0"/>

  <axis xyz="0 1 0"/>

  <limit lower="-1.57"
         upper="1.57"
         effort="10"
         velocity="1"/>

</joint>

<ros2_control name="GazeboSystem" type="system">

  <hardware>
    <plugin>gazebo_ros2_control/GazeboSystem</plugin>
  </hardware>

  <joint name="arm_joint">
    <command_interface name="position"/>
    <state_interface name="position"/>
    <state_interface name="velocity"/>
  </joint>

</ros2_control>

<gazebo>
  <plugin name="gazebo_ros2_control" filename="libgazebo_ros2_control.so">
    <parameters>/home/diseq1/ros2_ws/src/gazebo_tutorial/config/joint_controller.yaml</parameters>
  </plugin>
</gazebo>

</robot>